File: dados-2/DSC.txt
CLOSED
Version	1.0
Language	English
Run	1
RunSerial	2425
Instrument	DSC Q100 V9.9 Build 303
Module	DSC Standard Cell FC
Operator	Fabi
File	\\Niger\ta\Data\DSC\2017\Geral\Karl_Prop 2,5 45%UR.002
ProcName	Karl
InstSerial	0100-1211
Sample	Prop 2,5 45%UR
Size	20.5000	mg
Method	Karl
Comment
Xcomment	Pan: Aluminum Hermetic
Xcomment	Gas1: Argon 50.0 ml/min
Xcomment	Gas2: None 0.0 ml/min
Text
Exotherm	UP
Kcell	1.09030
Calib	-11.7822
TempCal	1	pts	158.71	156.60
TzeroDt	-90.0515 -0.0093 2.2263
TzeroDtz	-90.0515 0.0466 2.4421
InstCalFile	Tzero: \\Niger\ta\Data\DSC\CALIBRATION\20122016\CALIBRATION\0_RCS_12_20_2016 17_23_31.TZR
InstCalFile	Baseline: \\Niger\ta\Data\DSC\CALIBRATION\20122016\L.Base 20122016
InstCalFile	Sapphire: \\Niger\ta\Data\DSC\CALIBRATION\20122016\Safira 20122017.001
InstCalDate	Tzero 2016-12-20 Time 19:23:31
TempRange	-90.04 to 395.23 °C at 19.96 °C/min Heat Only
AutoZero	Delta T Offset 0.000 uV
AutoZero	Delta T0 Offset 0.000 uV
Controls	Gas 1  Event Off  Sampling 0.2
Cell#	FC-02451
CoolingUnit	RCS
SelHeatFlow	Heat Flow T4 (mW)
AutoAnalysis	Off
MacroFile
Nsig	4
Sig1	Time (min)
Sig2	Temperature (°C)
Sig3	Heat Flow (mW)
Sig4	Sample Purge Flow (mL/min)
Date	2017-08-04
Time	14:41:29
OrgMethod	1: Equilibrate at 10.00 °C
OrgMethod	2: Ramp 2.00 °C/min to 55.00 °C
OrgMethod	3: Isothermal for 2.00 min
OrgMethod	4: Ramp 2.00 °C/min to 5.00 °C
OrgFile	C:\TA\Data\DSC\2017\Geral\Karl_Prop 2,5 45%UR.002
3.33324E-4 10.28956 2.838133 50.11103
0.03699998 10.26548 2.599159 50.23934
0.07366666 10.25428 2.373009 49.90915
0.1103334 10.26416 2.151790 50.01864
0.1470000 10.28549 1.918331 50.09665
0.1836666 10.31326 1.677242 50.00896
0.2203333 10.34684 1.434023 50.10598
0.2570000 10.38371 1.195789 49.95108
0.2936666 10.42296 0.9643345 49.89898
0.3303334 10.46581 0.7429111 50.05154
0.3670000 10.51041 0.5341592 50.01504
0.4036667 10.55768 0.3323159 49.92078
0.4403334 10.60737 0.1415409 50.04328
0.4770000 10.65819 -.02476988 50.17902
0.5136667 10.71134 -0.1941874 50.09122
0.5503332 10.76640 -0.3457613 50.04200
0.5870000 10.82196 -0.4830422 49.99408
0.6236668 10.88040 -0.6134863 50.18611
0.6603332 10.93928 -0.7343472 49.93906
0.6970000 10.99930 -0.8440008 50.00324
0.7336668 11.06016 -0.9489454 49.85480
0.7703332 11.12132 -1.044424 50.10445
0.8070000 11.18447 -1.127851 50.05941
0.8436668 11.24908 -1.210172 50.15810
0.8803332 11.31271 -1.285599 49.93844
0.9170000 11.37829 -1.352577 49.87133
0.9536668 11.44418 -1.413345 49.99400
0.9903334 11.51011 -1.471996 49.97143
1.027000 11.57720 -1.523867 49.98414
1.063667 11.64413 -1.576061 49.94833
1.100334 11.71210 -1.624431 50.05235
1.137000 11.77998 -1.662731 50.19731
1.173667 11.84940 -1.700684 49.98692
1.210334 11.91784 -1.735182 49.81360
1.247000 11.98700 -1.769972 49.99707
1.283667 12.05677 -1.797545 50.04498
1.320334 12.12652 -1.824343 49.98832
1.357000 12.19676 -1.851832 50.07272
1.393667 12.26698 -1.876949 49.88581
1.430333 12.33696 -1.900859 50.08154
1.467000 12.40766 -1.924728 50.02031
1.503667 12.47870 -1.943746 50.08496
1.540334 12.54906 -1.961184 50.11033
1.577000 12.61984 -1.977146 50.04902
1.613667 12.69165 -1.999623 49.86674
1.650333 12.76274 -2.016427 50.07274
1.687000 12.83458 -2.029985 49.86070
1.723667 12.90622 -2.036543 50.04148
1.760333 12.97839 -2.044837 50.02274
1.797000 13.04917 -2.054863 49.94831
1.833667 13.12071 -2.065044 49.90539
1.870334 13.19404 -2.072346 50.04059
1.907000 13.26578 -2.081899 50.07368
1.943667 13.33790 -2.088561 50.04238
1.980333 13.41035 -2.095169 50.08764
2.017000 13.48229 -2.103575 49.97444
2.053667 13.55361 -2.145335 50.05591
2.090333 13.62556 -2.157467 49.95877
2.127000 13.69784 -2.161123 49.90914
2.163667 13.77063 -2.164075 50.08228
2.200334 13.84371 -2.167410 50.17650
2.237000 13.91551 -2.171380 49.92053
2.273666 13.98821 -2.178606 49.94213
2.310333 14.06157 -2.182918 50.01369
2.347000 14.13436 -2.187233 50.00230
2.383667 14.20709 -2.201323 49.93480
2.420334 14.27777 -2.208576 50.08772
2.457000 14.35102 -2.212660 49.93625
2.493667 14.42406 -2.216270 49.94551
2.530333 14.49681 -2.219662 50.00656
2.567000 14.56986 -2.223404 49.93304
2.603667 14.64238 -2.228524 49.87774
2.640333 14.71495 -2.233076 49.91209
2.677000 14.78736 -2.238377 50.01946
2.713667 14.85994 -2.243306 50.03089
2.750333 14.93243 -2.248929 49.85348
2.787000 15.00632 -2.253490 50.00390
2.823667 15.07769 -2.258211 50.04852
2.860334 15.15058 -2.262804 49.98906
2.897000 15.22438 -2.267336 49.85509
2.933667 15.29734 -2.272230 49.82213
2.970333 15.36944 -2.280260 49.97481
3.007000 15.44207 -2.284602 50.10004
3.043667 15.51556 -2.288061 50.11584
3.080333 15.58885 -2.291137 49.87989
3.117000 15.66204 -2.293618 49.97616
3.153667 15.73434 -2.296356 49.82631
3.190333 15.80801 -2.304258 49.96787
3.227000 15.88005 -2.352359 49.89742
3.263666 15.95075 -2.356193 50.01734
3.300333 16.02409 -2.357184 49.89770
3.337000 16.09768 -2.358114 49.83308
3.373667 16.16995 -2.359035 49.94314
3.410333 16.24261 -2.386181 49.89922
3.447000 16.30325 -2.820352 49.80252
3.483667 16.35784 -3.032843 49.95430
3.520333 16.41582 -3.070588 50.19434
3.557000 16.48449 -3.023776 50.05520
3.593667 16.55744 -2.969136 49.99384
3.630333 16.63374 -2.912986 49.98438
3.667000 16.71061 -2.865796 49.81250
3.703667 16.78636 -2.826416 50.12654
3.740333 16.86392 -2.792189 49.92216
3.777000 16.94030 -2.755151 50.01413
3.813666 17.01641 -2.724701 49.98594
3.850333 17.09257 -2.697420 49.92222
3.887000 17.16760 -2.669210 50.12165
3.923666 17.24362 -2.644194 50.15387
3.960333 17.32025 -2.619010 49.94266
3.997000 17.39506 -2.602696 49.91447
4.033667 17.47032 -2.583184 50.00836
4.070334 17.54474 -2.565997 50.11309
4.107000 17.62008 -2.550871 50.00424
4.143667 17.69397 -2.537111 50.01697
4.180333 17.76846 -2.527384 50.06036
4.217000 17.84439 -2.518547 49.94966
4.253666 17.91798 -2.505642 50.13796
4.290333 17.99263 -2.496304 50.02238
4.327000 18.06588 -2.488866 49.97400
4.363666 18.14062 -2.483507 49.89672
4.400333 18.21509 -2.477634 50.02152
4.437000 18.28820 -2.472990 49.89160
4.473666 18.36211 -2.468516 50.09178
4.510334 18.43549 -2.463838 49.84234
4.547000 18.50941 -2.459164 50.01653
4.583667 18.58269 -2.454950 49.92652
4.620333 18.65578 -2.451330 49.92428
4.657000 18.73026 -2.447998 49.99610
4.693666 18.80293 -2.445003 49.93812
4.730333 18.87543 -2.442465 50.00781
4.767000 18.94896 -2.441344 50.14699
4.803666 19.02268 -2.440063 49.86856
4.840334 19.09609 -2.439325 49.96796
4.877000 19.16924 -2.438567 49.94531
4.913666 19.24090 -2.437836 49.95630
4.950333 19.31492 -2.439142 50.07389
4.987000 19.38800 -2.440694 49.86159
5.023666 19.46068 -2.443095 50.00270
5.060333 19.53358 -2.445645 49.98868
5.097000 19.60632 -2.449935 50.04331
5.133666 19.67804 -2.485568 49.95616
5.170333 19.74915 -2.506883 50.12174
5.207000 19.82278 -2.506607 50.02692
5.243668 19.89683 -2.505363 50.09132
5.280334 19.96924 -2.504646 50.15525
5.317000 20.04282 -2.504174 50.11440
5.353668 20.11584 -2.504726 50.17311
5.390332 20.18819 -2.508480 49.88652
5.427000 20.26121 -2.509958 49.94558
5.463666 20.33554 -2.511250 50.07226
5.500332 20.40645 -2.531329 50.15040
5.537000 20.47880 -2.540198 49.97354
5.573666 20.55228 -2.542104 50.03757
5.610332 20.62463 -2.544142 49.94904
5.647000 20.69785 -2.546337 50.03206
5.683666 20.77076 -2.575735 50.00334
5.720332 20.84233 -2.594990 50.08451
5.757000 20.91539 -2.595092 49.97098
5.793668 20.98873 -2.594601 50.08993
5.830332 21.06244 -2.593717 50.08111
5.867000 21.13476 -2.594070 50.13102
5.903668 21.20705 -2.600766 49.94869
5.940332 21.27844 -2.611292 50.03248
5.977000 21.35138 -2.616563 50.13791
6.013666 21.42493 -2.619623 49.93840
6.050332 21.49847 -2.621435 49.87404
6.087000 21.57032 -2.630564 50.04711
6.123668 21.64330 -2.638569 49.81472
6.160332 21.71483 -2.684312 50.10176
6.197000 21.78629 -2.706699 50.01626
6.233668 21.85899 -2.707399 50.03109
6.270332 21.93258 -2.706500 50.03194
6.307000 22.00438 -2.745120 50.11204
6.343666 22.07404 -2.810688 50.13684
6.380332 22.14616 -2.798779 49.94522
6.417000 22.21910 -2.794816 49.96422
6.453668 22.29330 -2.789265 50.05407
6.490332 22.36578 -2.784786 49.97980
6.527000 22.44010 -2.781810 50.05880
6.563666 22.51166 -2.791338 49.92420
6.600332 22.58479 -2.791878 50.14424
6.637000 22.65807 -2.791020 50.18498
6.673666 22.73058 -2.803820 50.06935
6.710332 22.80354 -2.819818 50.04984
6.747000 22.87516 -2.826926 50.03701
6.783668 22.94674 -2.831368 49.99735
6.820334 23.02020 -2.842085 49.96678
6.857000 23.09055 -2.882134 49.88022
6.893668 23.16150 -2.927179 50.11521
6.930332 23.23326 -2.936770 49.97480
6.967000 23.30690 -2.936802 49.96684
7.003668 23.37924 -2.936176 49.96034
7.040332 23.45134 -2.955981 49.92068
7.077000 23.52174 -3.021294 50.02934
7.113666 23.59306 -3.023105 49.91980
7.150332 23.66508 -3.023112 49.97835
7.187000 23.73849 -3.029024 50.04243
7.223666 23.80879 -3.073940 50.10515
7.260332 23.87899 -3.146870 50.12188
7.297000 23.94947 -3.172058 49.91368
7.333668 24.01875 -3.245044 49.98410
7.370332 24.08712 -3.324460 49.90860
7.407000 24.15545 -3.330944 49.82108
7.443666 24.22694 -3.363128 49.96184
7.480332 24.29536 -3.400273 50.17517
7.517000 24.36675 -3.424250 50.05544
7.553668 24.43708 -3.467860 49.92436
7.590332 24.50743 -3.512264 50.03140
7.627000 24.57786 -3.565384 49.90799
7.663666 24.64533 -3.731538 49.91906
7.700332 24.70756 -3.900200 50.06873
7.737000 24.77226 -3.918117 49.81784
7.773668 24.84124 -3.918265 50.09559
7.810332 24.91101 -3.928000 50.15388
7.847000 24.98248 -3.941201 50.21143
7.883668 25.05390 -3.970184 49.95363
7.920332 25.12458 -4.027406 49.94038
7.957000 25.19585 -4.049236 49.95340
7.993668 25.26462 -4.097268 49.97688
8.030334 25.33041 -4.367806 49.97850
8.067000 25.39038 -4.513463 49.89566
8.103668 25.45618 -4.466941 49.94702
8.140332 25.52887 -4.445613 50.14220
8.177000 25.60188 -4.443140 49.88006
8.213668 25.67355 -4.444384 50.08467
8.250334 25.74597 -4.450805 50.01264
8.287000 25.81816 -4.461722 49.98613
8.323666 25.89102 -4.471752 50.09678
8.360332 25.96324 -4.502563 50.01039
8.397000 26.03504 -4.525912 49.85472
8.433666 26.10684 -4.532740 49.88830
8.470332 26.17818 -4.536209 49.96907
8.507000 26.25095 -4.581264 50.04642
8.543668 26.32142 -4.620268 49.87769
8.580334 26.39386 -4.620562 49.96735
8.617000 26.46604 -4.620446 50.13842
8.653668 26.53959 -4.622300 50.16698
8.690332 26.61220 -4.625180 50.02936
8.727001 26.68505 -4.629596 49.99083
8.763668 26.75642 -4.647696 49.91691
8.800332 26.82884 -4.655890 49.97459
8.837000 26.90090 -4.661563 49.92468
8.873666 26.97322 -4.689728 49.96619
8.910332 27.04565 -4.697956 49.91139
8.947000 27.11753 -4.710518 50.17021
8.983666 27.18982 -4.726562 49.96697
9.020332 27.26294 -4.729696 50.08844
9.057000 27.33563 -4.733494 49.95761
9.093668 27.40744 -4.755363 49.90043
9.130332 27.47976 -4.765992 49.96766
9.167000 27.55336 -4.770370 49.99694
9.203668 27.62567 -4.775078 49.90739
9.240332 27.69844 -4.778630 49.92438
9.277001 27.77113 -4.785388 50.00228
9.313666 27.84388 -4.788560 50.18748
9.350332 27.91792 -4.802324 49.97853
9.387000 27.98943 -4.822488 49.93484
9.423668 28.06100 -4.892562 49.99294
9.460332 28.12958 -4.961959 49.88556
9.497000 28.19937 -4.983564 50.07199
9.533668 28.27140 -4.980229 50.00461
9.570334 28.34483 -4.972976 50.11328
9.607001 28.41879 -4.969866 50.07431
9.643666 28.49190 -4.967258 49.91156
9.680332 28.56552 -4.966320 49.97672
9.717000 28.63768 -4.965557 49.95203
9.753668 28.71076 -4.965493 50.10254
9.790332 28.78514 -4.965360 49.92055
9.827000 28.85730 -4.965537 49.88166
9.863666 28.93042 -4.973129 49.94367
9.900332 29.00278 -4.982074 49.91898
9.937000 29.06957 -5.182086 49.81816
9.973668 29.13942 -5.132139 49.84568
10.01033 29.21325 -5.099294 50.03930
10.04700 29.28809 -5.085168 50.09526
10.08367 29.36277 -5.076552 49.87475
10.12033 29.43740 -5.070118 50.01248
10.15700 29.51138 -5.065286 50.08488
10.19367 29.58605 -5.061187 49.92914
10.23033 29.65878 -5.056884 49.95340
10.26700 29.73293 -5.052770 49.90346
10.30367 29.80626 -5.047306 50.13378
10.34033 29.87989 -5.042903 50.20642
10.37700 29.95408 -5.038668 50.08126
10.41367 30.02839 -5.034664 49.97619
10.45033 30.10150 -5.030790 50.07174
10.48700 30.17484 -5.026656 49.90746
10.52367 30.24810 -5.023538 50.06896
10.56033 30.32160 -5.019614 50.06430
10.59700 30.39463 -5.015787 49.96783
10.63367 30.46819 -5.011976 50.03070
10.67033 30.54278 -5.008117 50.10246
10.70700 30.61537 -5.003772 49.91990
10.74367 30.68986 -4.998708 50.00476
10.78033 30.76424 -4.993072 50.03544
10.81700 30.83880 -4.986631 50.03979
10.85367 30.91219 -4.978114 50.07309
10.89033 30.98694 -4.968050 49.93309
10.92700 31.06052 -4.958190 49.91275
10.96367 31.13494 -4.944252 50.07862
11.00034 31.21036 -4.934012 49.98365
11.03700 31.28447 -4.927687 49.82787
11.07367 31.35730 -4.921534 50.04332
11.11033 31.43112 -4.912188 49.92538
11.14700 31.50634 -4.900656 49.86383
11.18366 31.57970 -4.892750 50.02706
11.22033 31.65403 -4.882219 49.99964
11.25700 31.72922 -4.868582 50.18183
11.29367 31.80314 -4.861720 50.01946
11.33033 31.87674 -4.849742 50.05686
11.36700 31.95074 -4.829758 50.19653
11.40367 32.02635 -4.806550 50.06938
11.44033 32.10102 -4.790722 49.90246
11.47700 32.17477 -4.768838 50.03412
11.51367 32.24951 -4.753787 50.04983
11.55033 32.32370 -4.736902 49.91986
11.58700 32.39877 -4.718716 49.93046
11.62367 32.47332 -4.703774 50.03722
11.66033 32.54835 -4.685726 50.00463
11.69700 32.62201 -4.666183 50.01795
11.73366 32.69756 -4.646446 50.07415
11.77033 32.77306 -4.624880 49.93972
11.80700 32.84740 -4.605004 50.08909
11.84367 32.92270 -4.587734 50.10208
11.88033 32.99750 -4.570612 49.83776
11.91700 33.07234 -4.551064 49.97120
11.95367 33.14685 -4.536558 50.00832
11.99033 33.22119 -4.527466 49.85934
12.02700 33.29620 -4.511961 50.11672
12.06367 33.37052 -4.497710 50.11000
12.10033 33.44511 -4.489107 49.93437
12.13700 33.51993 -4.481759 49.80313
12.17367 33.59101 -4.523675 50.07797
12.21033 33.66418 -4.516567 49.99656
12.24700 33.73783 -4.499598 50.05204
12.28367 33.81245 -4.488471 49.96231
12.32034 33.88594 -4.483270 49.96046
12.35700 33.96070 -4.478266 49.80356
12.39366 34.03416 -4.472926 50.23496
12.43033 34.10879 -4.467972 50.00104
12.46700 34.18122 -4.463896 50.02148
12.50367 34.25421 -4.460290 50.17400
12.54033 34.32804 -4.458277 50.05733
12.57700 34.40100 -4.457118 49.88760
12.61367 34.47359 -4.456662 49.83456
12.65033 34.54680 -4.456717 50.07250
12.68700 34.62008 -4.456973 50.01740
12.72367 34.69365 -4.457350 49.82308
12.76033 34.76626 -4.458096 49.86100
12.79700 34.84010 -4.458082 49.92064
12.83367 34.91348 -4.457050 50.12000
12.87034 34.98773 -4.454900 50.09752
12.90700 35.06180 -4.451712 50.05586
12.94366 35.13445 -4.447318 49.81700
12.98033 35.20956 -4.439910 50.01538
13.01700 35.28348 -4.432534 49.96860
13.05367 35.35788 -4.428211 50.04446
13.09033 35.43174 -4.409106 49.93214
13.12700 35.50644 -4.397164 50.12280
13.16367 35.58175 -4.380330 50.00504
13.20034 35.65568 -4.358829 50.01513
13.23700 35.73072 -4.335972 49.92578
13.27367 35.80578 -4.312540 49.93813
13.31033 35.87990 -4.294536 50.03803
13.34700 35.95488 -4.270553 50.00508
13.38367 36.03072 -4.245280 50.03808
13.42033 36.10516 -4.216960 50.10767
13.45700 36.18098 -4.190082 49.93058
13.49366 36.25583 -4.169803 49.99257
13.53033 36.33241 -4.147412 50.13550
13.56700 36.40686 -4.120239 50.04572
13.60367 36.48222 -4.094505 50.00470
13.64033 36.55730 -4.066860 49.99259
13.67700 36.63304 -4.041444 50.00912
13.71367 36.70825 -4.015709 50.10437
13.75034 36.78308 -3.982368 49.93378
13.78700 36.86008 -3.952716 49.98991
13.82367 36.93525 -3.921468 49.98303
13.86033 37.01068 -3.892865 50.02572
13.89700 37.08734 -3.863306 49.98350
13.93367 37.16206 -3.837926 50.06625
13.97034 37.23884 -3.805626 50.12822
14.00700 37.31372 -3.774630 49.97638
14.04367 37.38987 -3.750613 50.04596
14.08034 37.46493 -3.727772 49.95914
14.11700 37.53995 -3.701594 49.92650
14.15367 37.61590 -3.667779 50.01071
14.19033 37.69117 -3.632080 50.15924
14.22700 37.76780 -3.607268 49.92668
14.26367 37.84238 -3.591990 49.92929
14.30033 37.91850 -3.567890 49.85547
14.33700 37.99406 -3.535369 50.02904
14.37367 38.06900 -3.506884 49.98314
14.41033 38.14470 -3.480670 50.01028
14.44700 38.22069 -3.446752 49.83200
14.48367 38.29534 -3.421086 49.88093
14.52034 38.37140 -3.401364 49.95216
14.55700 38.44634 -3.385770 50.08600
14.59367 38.52232 -3.361645 49.97873
14.63033 38.59728 -3.334826 49.89667
14.66700 38.67225 -3.312326 49.97382
14.70367 38.74746 -3.295012 49.95048
14.74033 38.82140 -3.282600 50.01240
14.77700 38.89734 -3.260172 50.12534
14.81366 38.97220 -3.238594 49.86894
14.85033 39.04715 -3.217057 50.09140
14.88700 39.12152 -3.201732 50.03758
14.92367 39.19691 -3.183060 50.00672
14.96033 39.27161 -3.163825 50.09766
14.99700 39.34645 -3.144996 50.02356
15.03367 39.42160 -3.130220 50.10566
15.07034 39.49642 -3.117542 49.82353
15.10700 39.57088 -3.106208 49.91866
15.14366 39.64463 -3.090251 50.05609
15.18033 39.71986 -3.070134 50.07219
15.21700 39.79536 -3.051778 50.04325
15.25367 39.86925 -3.037030 50.12528
15.29033 39.94352 -3.023447 50.03572
15.32700 40.01916 -3.009623 50.13609
15.36366 40.09198 -3.001108 49.81690
15.40033 40.16718 -2.991637 49.93098
15.43700 40.24109 -2.981688 50.17008
15.47367 40.31630 -2.969724 49.96492
15.51033 40.39025 -2.953466 50.11062
15.54700 40.46522 -2.929978 50.09458
15.58367 40.53918 -2.915025 49.93814
15.62034 40.61405 -2.903504 49.92431
15.65700 40.68897 -2.897020 50.07468
15.69366 40.76236 -2.880914 50.03882
15.73033 40.83704 -2.867834 49.90484
15.76700 40.91138 -2.862461 50.01040
15.80367 40.98426 -2.858282 50.20451
15.84033 41.05870 -2.850108 49.92785
15.87700 41.13347 -2.840206 49.92575
15.91367 41.20698 -2.833376 49.93570
15.95034 41.28066 -2.827779 50.13953
15.98700 41.35556 -2.819597 50.04904
16.02367 41.42906 -2.810873 50.06699
16.06033 41.50302 -2.803004 50.07044
16.09700 41.57690 -2.797592 50.14910
16.13366 41.64947 -2.791950 49.73614
16.17033 41.72452 -2.783400 50.05350
16.20700 41.79867 -2.776492 49.89346
16.24366 41.87166 -2.770881 50.06289
16.28033 41.94553 -2.765336 49.95736
16.31700 42.01928 -2.760160 49.88399
16.35367 42.09341 -2.755200 49.95848
16.39034 42.16728 -2.750181 49.97356
16.42700 42.24072 -2.744841 49.92703
16.46366 42.31342 -2.739832 50.10297
16.50033 42.38735 -2.734668 50.00294
16.53700 42.46152 -2.729165 50.03824
16.57367 42.53567 -2.723285 50.05662
16.61034 42.60929 -2.717655 50.06744
16.64700 42.68266 -2.712198 50.13531
16.68367 42.75748 -2.706672 49.95066
16.72034 42.83160 -2.700808 49.90049
16.75700 42.90446 -2.695387 50.00742
16.79366 42.97798 -2.690275 50.00082
16.83033 43.05126 -2.685869 49.83533
16.86700 43.12406 -2.683846 49.99517
16.90366 43.19804 -2.681596 49.97970
16.94033 43.27168 -2.678225 49.88070
16.97700 43.34462 -2.674163 49.90824
17.01366 43.41944 -2.670026 49.98058
17.05033 43.49311 -2.665962 49.98060
17.08700 43.56638 -2.661737 49.89658
17.12366 43.64038 -2.657330 49.92559
17.16033 43.71422 -2.652970 49.91960
17.19700 43.78824 -2.649153 50.00472
17.23366 43.86118 -2.645784 50.00497
17.27033 43.93430 -2.643104 49.94063
17.30700 44.00765 -2.639672 50.05950
17.34366 44.08059 -2.636248 49.92775
17.38034 44.15464 -2.632636 50.01438
17.41700 44.22760 -2.628957 49.85066
17.45366 44.30180 -2.625975 50.06410
17.49033 44.37460 -2.623000 50.07848
17.52700 44.44848 -2.619494 50.03617
17.56366 44.52317 -2.616058 49.97286
17.60033 44.59528 -2.613424 49.91707
17.63700 44.66852 -2.610907 50.02043
17.67367 44.74216 -2.607872 49.97148
17.71034 44.81644 -2.605114 49.92216
17.74700 44.88918 -2.602670 50.12182
17.78367 44.96206 -2.600744 50.01869
17.82033 45.03702 -2.598352 49.98046
17.85700 45.11000 -2.595460 50.06972
17.89366 45.18309 -2.592114 49.99550
17.93033 45.25718 -2.588570 50.00228
17.96700 45.33136 -2.585781 49.90185
18.00366 45.40276 -2.586164 49.96946
18.04033 45.47687 -2.585100 50.15629
18.07700 45.55138 -2.582826 49.88989
18.11366 45.62410 -2.579965 49.94960
18.15033 45.69802 -2.576873 50.00867
18.18700 45.77160 -2.573468 49.98941
18.22366 45.84628 -2.569936 50.04163
18.26033 45.91885 -2.566188 49.88598
18.29700 45.99368 -2.562262 50.07203
18.33366 46.06684 -2.558513 50.07618
18.37033 46.14074 -2.554460 49.99106
18.40700 46.21402 -2.550610 49.86188
18.44366 46.28744 -2.546708 49.88496
18.48034 46.36188 -2.543094 49.90554
18.51700 46.43530 -2.539760 50.17740
18.55366 46.50928 -2.536744 49.97164
18.59033 46.58230 -2.534288 49.86266
18.62700 46.65496 -2.531401 49.88313
18.66366 46.72854 -2.528482 49.82874
18.70033 46.80314 -2.525556 49.90230
18.73700 46.87590 -2.522736 50.08407
18.77367 46.94954 -2.520207 50.14636
18.81034 47.02321 -2.517610 49.93850
18.84700 47.09716 -2.514947 49.95062
18.88366 47.17031 -2.512875 50.12406
18.92033 47.24294 -2.511063 49.96308
18.95700 47.31680 -2.509192 50.08176
18.99366 47.39094 -2.507096 49.97183
19.03034 47.46375 -2.505321 49.94280
19.06700 47.53760 -2.502974 49.86606
19.10367 47.61090 -2.500331 50.04928
19.14034 47.68404 -2.497991 49.96336
19.17700 47.75824 -2.495654 49.95378
19.21366 47.83174 -2.493051 49.86690
19.25033 47.90489 -2.490309 49.78803
19.28700 47.97870 -2.487703 50.12553
19.32367 48.05288 -2.484806 49.90469
19.36034 48.12606 -2.481794 50.01494
19.39700 48.19904 -2.478666 50.05998
19.43367 48.27322 -2.475980 50.10773
19.47034 48.34619 -2.473627 50.04428
19.50700 48.41996 -2.471370 50.08600
19.54366 48.49360 -2.468786 50.00383
19.58033 48.56644 -2.466079 49.91932
19.61700 48.63982 -2.464850 50.14083
19.65366 48.71381 -2.465210 49.92778
19.69033 48.78567 -2.466062 50.01817
19.72700 48.85836 -2.466312 49.90220
19.76366 48.93216 -2.465991 50.02281
19.80033 49.00624 -2.465205 50.06426
19.83700 49.08016 -2.464176 50.07236
19.87366 49.15280 -2.462786 49.99762
19.91033 49.22742 -2.461153 49.93945
19.94700 49.29984 -2.459956 50.04355
19.98366 49.37424 -2.458548 50.05264
20.02033 49.44663 -2.456596 49.99400
20.05700 49.52166 -2.454911 49.89016
20.09366 49.59538 -2.452734 50.04950
20.13034 49.66772 -2.450480 50.00418
20.16700 49.74161 -2.448168 50.04309
20.20366 49.81516 -2.446146 49.79741
20.24033 49.88889 -2.444234 49.97484
20.27700 49.96162 -2.442820 50.14176
20.31366 50.03488 -2.441482 49.99802
20.35033 50.10902 -2.440424 49.95611
20.38700 50.18183 -2.439815 49.98286
20.42367 50.25540 -2.439728 49.83892
20.46034 50.32766 -2.441472 50.04078
20.49700 50.39981 -2.445110 49.87240
20.53367 50.47334 -2.446680 50.09082
20.57033 50.54630 -2.447532 49.80871
20.60700 50.62034 -2.448306 49.84658
20.64366 50.69291 -2.451242 49.99820
20.68033 50.76528 -2.457164 49.80828
20.71700 50.83828 -2.459890 49.98559
20.75366 50.91226 -2.461592 50.06074
20.79033 50.98518 -2.463368 49.88772
20.82700 51.05818 -2.465104 50.04322
20.86367 51.13142 -2.467843 50.04239
20.90033 51.20338 -2.471136 50.02972
20.93700 51.27719 -2.474100 49.91310
20.97366 51.35000 -2.476746 49.94632
21.01033 51.42272 -2.479613 50.08428
21.04700 51.49578 -2.484426 49.98476
21.08366 51.56870 -2.488852 50.19412
21.12033 51.64240 -2.491799 49.90052
21.15700 51.71625 -2.494453 49.79406
21.19367 51.78873 -2.496519 50.05641
21.23033 51.86092 -2.500965 49.89634
21.26700 51.93311 -2.508802 50.09266
21.30366 52.00613 -2.517282 50.07498
21.34033 52.07984 -2.520636 49.79904
21.37700 52.15256 -2.524878 50.03750
21.41367 52.22474 -2.531590 50.11522
21.45033 52.29704 -2.547989 49.89122
21.48700 52.37011 -2.551248 50.11894
21.52367 52.44384 -2.552393 49.94772
21.56033 52.51797 -2.552197 49.97914
21.59700 52.59126 -2.551258 49.94176
21.63366 52.66508 -2.550720 50.11602
21.67033 52.73785 -2.550820 49.86346
21.70700 52.81143 -2.553133 50.06208
21.74367 52.88354 -2.555508 50.08588
21.78033 52.95657 -2.556771 49.92459
21.81700 53.03037 -2.557427 49.91130
21.85367 53.10370 -2.557568 49.97083
21.89034 53.17828 -2.557527 49.77730
21.92700 53.25048 -2.557558 50.00614
21.96367 53.32430 -2.558117 49.90202
22.00033 53.39739 -2.559972 50.06564
22.03700 53.47045 -2.561356 50.02932
22.07367 53.54351 -2.562869 50.07524
22.11033 53.61600 -2.565732 49.97835
22.14700 53.68944 -2.568772 49.89284
22.18367 53.76236 -2.571236 49.96518
22.22034 53.83484 -2.574340 50.09462
22.25700 53.90825 -2.585756 49.89952
22.29366 53.98084 -2.589608 50.11144
22.33033 54.05410 -2.592171 49.91730
22.36700 54.12706 -2.596222 49.89236
22.40366 54.20024 -2.602693 49.90515
22.44033 54.27216 -2.609012 49.80306
22.47700 54.34586 -2.612408 49.80102
22.51367 54.41895 -2.615816 49.90819
22.55033 54.48800 -2.619751 50.04776
22.58700 54.54131 -2.624741 49.70270
22.62366 54.57957 -2.628186 49.87026
22.66033 54.61094 -2.603574 50.16076
22.69700 54.63582 -2.517248 49.85746
22.73366 54.65967 -2.411986 50.00574
22.77033 54.68090 -2.303350 49.95928
22.80700 54.70084 -2.198782 50.13715
22.84367 54.71782 -2.105615 50.18884
22.88033 54.73250 -2.018748 49.96640
22.91700 54.74668 -1.907426 49.91037
22.95366 54.75961 -1.811816 49.96033
22.99033 54.77178 -1.717881 49.92832
23.02700 54.78374 -1.637080 49.97810
23.06367 54.79317 -1.556127 49.95320
23.10033 54.80106 -1.493867 49.82916
23.13700 54.81059 -1.424973 49.83410
23.17367 54.81914 -1.363186 50.09096
23.21033 54.82546 -1.299568 50.12563
23.24700 54.83130 -1.252212 50.05094
23.28367 54.83750 -1.203028 49.94496
23.32033 54.84305 -1.155343 50.09020
23.35700 54.84780 -1.111983 50.03324
23.39366 54.85198 -1.089438 49.92840
23.43033 54.85570 -1.067976 49.93837
23.46700 54.85859 -1.061045 49.96379
23.50366 54.86012 -1.053745 49.96782
23.54033 54.86111 -1.044520 50.10838
23.57700 54.86459 -1.012277 50.02610
23.61367 54.86684 -0.9828137 49.96766
23.65033 54.87000 -0.9652022 49.84460
23.68700 54.87131 -0.9443625 49.79649
23.72366 54.87440 -0.9258795 50.03416
23.76033 54.87630 -0.9149988 49.99195
23.79700 54.87700 -0.9081944 49.82398
23.83366 54.87906 -0.9041153 50.15547
23.87033 54.87961 -0.8994980 50.03842
23.90700 54.88105 -0.8928130 50.13716
23.94367 54.88228 -0.8812934 49.94524
23.98033 54.88343 -0.8699952 49.98516
24.01700 54.88492 -0.8590903 50.00490
24.05366 54.88657 -0.8473149 49.95557
24.09033 54.88678 -0.8406981 49.97156
24.12700 54.88802 -0.8327610 49.92682
24.16367 54.88910 -0.8273332 50.10406
24.20033 54.88924 -0.8209740 50.09018
24.23700 54.89004 -0.8137450 49.91934
24.27367 54.89026 -0.8083406 49.93508
24.31033 54.88892 -0.8343993 49.93518
24.34700 54.88810 -0.8384247 49.96507
24.38366 54.88762 -0.8383640 50.02324
24.42033 54.88752 -0.8377090 50.11870
24.45700 54.88762 -0.8360303 49.97049
24.49367 54.88839 -0.8336620 49.94856
24.53033 54.88770 -0.8313759 50.05268
24.56700 54.87906 -0.8300138 50.08232
24.60367 54.85159 -0.8296947 49.93959
24.64034 54.81188 -0.7959866 50.11535
24.67700 54.76736 -0.6947965 50.04806
24.71367 54.71824 -0.5855803 49.89582
24.75033 54.66709 -0.4653572 49.96445
24.78700 54.61492 -0.3462018 49.97000
24.82367 54.56070 -0.2245940 49.98838
24.86033 54.50537 -0.1022179 50.05012
24.89700 54.44679 0.01084626 49.92850
24.93367 54.38806 0.1151296 49.92416
24.97034 54.32761 0.2153158 49.90424
25.00700 54.26709 0.3139904 49.98984
25.04366 54.20440 0.4049433 50.01547
25.08033 54.14215 0.4899472 50.01352
25.11700 54.07700 0.5633569 50.01504
25.15366 54.01191 0.6335126 49.89091
25.19033 53.94652 0.7041936 50.16726
25.22700 53.87943 0.7696845 50.06640
25.26367 53.81451 0.8256426 49.86508
25.30033 53.74674 0.8782824 49.95190
25.33700 53.67859 0.9308551 50.06199
25.37366 53.61025 0.9737489 49.94578
25.41033 53.54243 1.019325 49.99570
25.44700 53.47242 1.057655 50.00907
25.48366 53.40412 1.094951 49.83829
25.52033 53.33455 1.130172 50.05004
25.55700 53.26540 1.164424 50.01453
25.59367 53.19441 1.194244 50.15512
25.63034 53.12532 1.223878 50.06604
25.66700 53.05522 1.249460 49.94500
25.70366 52.98410 1.280377 50.13371
25.74033 52.91344 1.305005 50.01316
25.77700 52.84312 1.332856 50.08516
25.81367 52.77210 1.356338 50.05162
25.85033 52.70132 1.381223 50.07297
25.88700 52.62969 1.400677 50.01488
25.92367 52.55914 1.417894 50.11338
25.96033 52.48791 1.434984 49.91375
25.99700 52.41637 1.453545 50.04068
26.03367 52.34474 1.470869 49.96270
26.07033 52.27268 1.483337 50.01213
26.10700 52.20072 1.496085 50.13898
26.14366 52.12926 1.510854 49.97567
26.18033 52.05690 1.522644 49.93980
26.21700 51.98538 1.534784 50.09266
26.25366 51.91372 1.549342 50.05533
26.29033 51.84094 1.559569 49.92743
26.32700 51.76848 1.569977 50.05611
26.36367 51.69762 1.579301 50.00068
26.40033 51.62490 1.588825 50.01980
26.43700 51.55242 1.598009 49.99870
26.47367 51.47988 1.607006 50.06430
26.51033 51.40734 1.614946 50.10066
26.54700 51.33463 1.624115 50.00014
26.58367 51.26318 1.631085 49.91036
26.62034 51.19018 1.639415 50.00296
26.65700 51.11760 1.647801 49.89674
26.69367 51.04574 1.655167 50.04705
26.73034 50.97228 1.663866 50.22714
26.76700 50.90082 1.671669 50.10410
26.80366 50.82813 1.679323 49.88934
26.84033 50.75486 1.686839 50.05890
26.87700 50.68182 1.694723 49.97784
26.91367 50.61007 1.701761 49.99082
26.95033 50.53647 1.708732 49.87562
26.98700 50.46400 1.715966 50.14738
27.02367 50.39158 1.722722 49.99512
27.06033 50.31859 1.729464 50.04812
27.09700 50.24600 1.736134 50.08780
27.13366 50.17276 1.742570 50.17156
27.17033 50.10138 1.749054 50.11756
27.20700 50.02843 1.755174 49.96016
27.24366 49.95531 1.761061 50.12731
27.28033 49.88248 1.767014 49.98416
27.31700 49.80964 1.772990 49.99926
27.35366 49.73719 1.778838 50.16707
27.39033 49.66489 1.784579 50.12243
27.42700 49.59204 1.790119 50.05831
27.46367 49.51881 1.795654 50.13264
27.50033 49.44609 1.801100 49.83404
27.53700 49.37324 1.806368 49.98850
27.57367 49.30078 1.811674 50.09558
27.61033 49.22774 1.816694 49.87217
27.64700 49.15567 1.821764 49.99007
27.68367 49.08188 1.826675 50.04977
27.72034 49.00930 1.831527 49.92268
27.75700 48.93680 1.836371 50.05848
27.79366 48.86358 1.841192 49.96234
27.83033 48.79081 1.845712 50.06337
27.86700 48.71743 1.850316 49.93766
27.90366 48.64465 1.854977 49.84190
27.94033 48.57208 1.859478 49.90904
27.97700 48.49841 1.863863 50.01496
28.01367 48.42592 1.868204 49.85567
28.05033 48.35232 1.872048 49.89850
28.08700 48.27988 1.876278 50.14403
28.12366 48.20668 1.880253 49.97526
28.16033 48.13350 1.884153 49.87911
28.19700 48.06134 1.887994 50.10148
28.23367 47.98736 1.891612 50.07163
28.27033 47.91456 1.895088 50.01848
28.30700 47.84150 1.898712 49.96545
28.34366 47.76887 1.902281 50.07367
28.38034 47.69601 1.905926 50.01950
28.41700 47.62252 1.909296 50.10404
28.45366 47.54990 1.912683 49.94654
28.49033 47.47669 1.916018 50.04956
28.52700 47.40328 1.919569 50.08088
28.56367 47.33100 1.922790 49.95438
28.60033 47.25785 1.926100 50.18218
28.63700 47.18382 1.929379 50.02533
28.67367 47.11198 1.932455 50.05072
28.71033 47.03894 1.935385 50.15344
28.74700 46.96616 1.938509 49.95810
28.78367 46.89242 1.941658 50.15367
28.82033 46.81940 1.944852 49.99972
28.85700 46.74598 1.947635 50.07752
28.89366 46.67297 1.950370 49.98197
28.93033 46.60034 1.953247 50.14964
28.96700 46.52754 1.955916 50.01820
29.00366 46.45392 1.958618 49.89725
29.04033 46.38102 1.961289 49.98474
29.07700 46.30758 1.963666 49.88242
29.11367 46.23490 1.966209 50.07489
29.15033 46.16228 1.968424 49.89566
29.18700 46.08812 1.970560 50.10070
29.22367 46.01526 1.972939 50.06949
29.26033 45.94217 1.975515 49.98310
29.29700 45.86972 1.977280 50.06426
29.33367 45.79508 1.979188 50.08494
29.37034 45.72412 1.981236 50.04676
29.40700 45.65075 1.983499 49.83338
29.44367 45.57691 1.985616 49.99016
29.48034 45.50430 1.987721 50.04184
29.51700 45.43097 1.989801 50.08161
29.55366 45.35808 1.991994 49.94449
29.59033 45.28487 1.994022 50.08400
29.62700 45.21150 1.995998 50.05068
29.66367 45.13824 1.998084 49.92648
29.70033 45.06515 2.000381 50.02169
29.73700 44.99170 2.002706 49.79148
29.77367 44.91874 2.004987 49.98484
29.81033 44.84594 2.007229 50.11144
29.84700 44.77296 2.009516 49.97750
29.88366 44.69997 2.011932 50.19966
29.92033 44.62662 2.014330 50.02730
29.95700 44.55354 2.016929 50.15630
29.99366 44.48044 2.019457 50.07919
30.03033 44.40660 2.021725 49.98898
30.06700 44.33435 2.024100 50.16939
30.10366 44.26111 2.026428 49.96824
30.14033 44.18717 2.028935 50.13149
30.17700 44.11550 2.031398 50.09535
30.21367 44.04295 2.033933 50.09583
30.25033 43.96860 2.036425 50.00604
30.28700 43.89610 2.038569 49.96050
30.32367 43.82240 2.040964 50.01953
30.36033 43.74906 2.043192 50.12006
30.39700 43.67640 2.045482 50.14180
30.43367 43.60326 2.047900 49.94821
30.47034 43.53042 2.050198 49.94702
30.50700 43.45724 2.052324 50.18299
30.54366 43.38420 2.054468 50.09814
30.58033 43.31052 2.056434 49.97584
30.61700 43.23820 2.058255 50.02015
30.65366 43.16480 2.060317 49.93622
30.69033 43.09131 2.062355 50.00798
30.72700 43.01880 2.064412 50.07950
30.76367 42.94476 2.066591 49.95108
30.80033 42.87320 2.068604 49.98278
30.83700 42.79970 2.070735 50.05322
30.87366 42.72624 2.072652 49.78524
30.91033 42.65378 2.074601 50.02850
30.94700 42.57956 2.076452 49.92875
30.98367 42.50639 2.078468 49.88138
31.02033 42.43344 2.080401 49.99100
31.05700 42.36034 2.082282 49.96582
31.09366 42.28715 2.084109 50.00921
31.13034 42.21335 2.085794 50.00528
31.16700 42.14124 2.087508 50.06641
31.20366 42.06754 2.089110 50.15639
31.24033 41.99424 2.090780 50.00369
31.27700 41.92194 2.092254 49.82221
31.31367 41.84822 2.093660 49.91488
31.35033 41.77519 2.095126 50.13904
31.38700 41.70261 2.096518 50.07900
31.42367 41.62930 2.097938 49.99928
31.46033 41.55538 2.099406 50.02906
31.49700 41.48303 2.100884 49.96766
31.53367 41.41018 2.102356 50.13682
31.57033 41.33668 2.103766 50.02058
31.60700 41.26306 2.105326 50.07294
31.64366 41.19043 2.106690 50.04528
31.68033 41.11728 2.108170 50.17126
31.71700 41.04383 2.109566 49.98775
31.75366 40.97135 2.111133 49.95139
31.79033 40.89678 2.112440 50.01266
31.82700 40.82445 2.113938 50.01562
31.86367 40.75137 2.115394 50.02688
31.90033 40.67770 2.116740 50.01738
31.93700 40.60446 2.118140 49.95804
31.97367 40.53186 2.119438 49.99190
32.01033 40.45808 2.120706 49.99695
32.04700 40.38483 2.122054 49.94322
32.08366 40.31156 2.123296 49.95610
32.12033 40.23906 2.124645 50.04297
32.15700 40.16546 2.125947 50.06048
32.19366 40.09239 2.127180 49.85389
32.23033 40.01898 2.128370 50.00452
32.26700 39.94683 2.129450 49.96156
32.30366 39.87189 2.130423 50.21232
32.34033 39.79910 2.131448 50.07800
32.37700 39.72656 2.132393 49.88031
32.41367 39.65324 2.133452 50.04989
32.45033 39.57968 2.134310 49.90964
32.48700 39.50686 2.135051 50.05514
32.52367 39.43374 2.135894 49.84060
32.56033 39.36091 2.136751 50.11978
32.59700 39.28722 2.137617 50.05484
32.63367 39.21372 2.138460 50.04920
32.67034 39.14115 2.139310 49.94274
32.70700 39.06760 2.140369 49.95448
32.74367 38.99404 2.141258 49.92436
32.78033 38.92166 2.142350 49.96038
32.81700 38.84783 2.143286 49.93720
32.85366 38.77489 2.143884 49.97168
32.89033 38.70089 2.144604 50.19738
32.92700 38.62788 2.145442 49.93266
32.96367 38.55498 2.146230 49.92310
33.00033 38.48154 2.147103 49.89300
33.03700 38.40855 2.147966 49.94580
33.07367 38.33544 2.148893 49.83490
33.11033 38.26208 2.149771 50.12000
33.14700 38.18867 2.150711 49.90805
33.18367 38.11609 2.151594 50.02720
33.22034 38.04196 2.152404 49.96445
33.25700 37.96990 2.153206 50.01636
33.29367 37.89619 2.154100 50.01162
33.33034 37.82313 2.154859 49.88656
33.36700 37.74869 2.155724 50.10872
33.40367 37.67628 2.156654 49.97037
33.44033 37.60339 2.157553 49.88675
33.47700 37.53034 2.158427 50.00600
33.51367 37.45658 2.159318 49.94810
33.55033 37.38272 2.160232 50.06871
33.58700 37.31003 2.161020 49.85746
33.62366 37.23746 2.161922 50.09037
33.66033 37.16455 2.162719 50.09624
33.69700 37.09113 2.163560 49.94630
33.73367 37.01690 2.164475 50.04000
33.77033 36.94428 2.165553 49.93989
33.80700 36.87084 2.166594 49.94594
33.84366 36.79801 2.167499 49.88406
33.88034 36.72385 2.168408 50.19133
33.91700 36.65078 2.169308 49.88952
33.95367 36.57825 2.170051 50.00500
33.99033 36.50453 2.170844 49.93193
34.02700 36.43115 2.171564 49.91064
34.06367 36.35850 2.172253 49.93134
34.10034 36.28522 2.172969 50.05830
34.13700 36.21175 2.173572 49.81666
34.17366 36.13840 2.174169 50.17984
34.21033 36.06578 2.174890 49.95330
34.24700 35.99168 2.175338 49.85874
34.28366 35.91904 2.175770 50.01736
34.32033 35.84602 2.176162 49.97210
34.35700 35.77189 2.176700 50.03230
34.39366 35.69889 2.177215 49.98850
34.43033 35.62598 2.177846 50.08567
34.46700 35.55256 2.178171 49.93000
34.50366 35.48037 2.178715 50.00188
34.54033 35.40654 2.179164 49.84246
34.57700 35.33234 2.179447 49.99954
34.61367 35.25996 2.179886 49.98920
34.65033 35.18624 2.180503 49.91720
34.68700 35.11322 2.180954 50.00033
34.72367 35.03925 2.181404 49.85426
34.76033 34.96676 2.181790 50.10379
34.79700 34.89354 2.182188 50.09869
34.83366 34.82016 2.182729 50.02906
34.87033 34.74790 2.183288 49.82114
34.90700 34.67370 2.183760 49.82590
34.94366 34.60044 2.184104 50.09652
34.98033 34.52730 2.184584 50.09180
35.01700 34.45474 2.185060 50.06489
35.05366 34.38012 2.185389 49.95576
35.09033 34.30871 2.185842 49.97468
35.12700 34.23380 2.186361 50.06694
35.16367 34.16109 2.186782 50.04235
35.20033 34.08743 2.187212 49.87628
35.23700 34.01394 2.187727 49.97260
35.27367 33.94224 2.188238 50.03524
35.31033 33.86810 2.188756 50.03778
35.34700 33.79511 2.189256 50.16285
35.38367 33.72195 2.189876 49.93756
35.42034 33.64804 2.190454 49.93705
35.45700 33.57556 2.190834 49.99057
35.49367 33.50200 2.191490 49.97200
35.53033 33.42820 2.192139 49.95062
35.56700 33.35550 2.192802 49.97066
35.60366 33.28205 2.193556 50.07466
35.64033 33.20922 2.194263 49.93611
35.67700 33.13611 2.194777 50.08322
35.71367 33.06249 2.195366 49.87534
35.75033 32.98905 2.196098 49.96466
35.78700 32.91558 2.196688 50.01034
35.82367 32.84338 2.197334 49.95016
35.86033 32.76906 2.197978 49.98966
35.89700 32.69720 2.198549 50.06522
35.93367 32.62380 2.199124 49.97272
35.97034 32.54999 2.199644 49.97141
36.00700 32.47687 2.200194 49.83242
36.04367 32.40332 2.200644 49.84879
36.08034 32.33008 2.201041 50.01046
36.11700 32.25688 2.201576 49.92672
36.15367 32.18286 2.202006 50.07458
36.19033 32.11030 2.202476 49.99860
36.22700 32.03798 2.202816 50.06774
36.26367 31.96421 2.203268 49.92169
36.30033 31.89055 2.203700 50.09874
36.33700 31.81724 2.204226 49.95858
36.37366 31.74430 2.204682 50.03426
36.41033 31.67068 2.205180 50.00009
36.44700 31.59678 2.205684 49.90906
36.48367 31.52402 2.206511 49.85292
36.52033 31.45084 2.207219 49.88869
36.55700 31.37781 2.208058 49.94192
36.59366 31.30466 2.209229 50.12908
36.63034 31.23158 2.210478 50.08443
36.66700 31.15812 2.211975 50.05024
36.70367 31.08510 2.213871 49.93906
36.74033 31.01203 2.216083 49.96104
36.77700 30.93902 2.218926 50.02628
36.81367 30.86692 2.222224 49.99954
36.85034 30.79394 2.226372 50.11842
36.88700 30.72254 2.232689 49.95407
36.92366 30.64964 2.241289 50.00389
36.96033 30.57644 2.254634 50.01834
36.99700 30.50484 2.274433 49.80333
37.03366 30.43328 2.299375 50.03812
37.07033 30.36140 2.330777 50.14436
37.10700 30.29076 2.366199 49.83765
37.14366 30.22010 2.400798 49.91848
37.18033 30.14922 2.443812 49.92305
37.21700 30.07870 2.488445 50.00096
37.25366 30.00861 2.538838 50.10644
37.29033 29.93970 2.592627 50.04846
37.32700 29.87026 2.648502 49.99590
37.36367 29.80172 2.710450 50.12036
37.40033 29.73342 2.776684 49.99594
37.43700 29.66556 2.848618 50.08670
37.47367 29.59788 2.923918 50.05290
37.51033 29.53080 3.002628 50.01583
37.54700 29.46314 3.084200 49.98988
37.58366 29.39649 3.167642 50.00422
37.62033 29.33057 3.258531 49.80924
37.65700 29.26442 3.343478 50.09668
37.69366 29.19742 3.432515 50.08430
37.73033 29.13114 3.524380 50.15454
37.76700 29.06616 3.615867 50.14482
37.80366 29.00125 3.702598 50.08144
37.84033 28.93510 3.793525 49.94396
37.87700 28.86812 3.878192 50.04285
37.91367 28.80172 3.970047 50.09506
37.95033 28.73508 4.042332 49.98902
37.98700 28.66908 4.127948 49.95149
38.02367 28.60210 4.197929 49.87766
38.06033 28.53602 4.274728 50.21172
38.09700 28.46790 4.341593 50.01238
38.13367 28.40123 4.401570 49.94242
38.17034 28.33294 4.464644 49.99625
38.20700 28.26539 4.522061 50.01489
38.24367 28.19651 4.572796 49.99954
38.28033 28.12740 4.621102 49.94529
38.31700 28.05750 4.664606 50.09984
38.35366 27.98888 4.705232 49.99433
38.39033 27.91964 4.742130 50.02214
38.42700 27.84948 4.773430 50.11787
38.46367 27.77782 4.801234 49.95782
38.50033 27.70737 4.823588 49.89725
38.53700 27.63586 4.840474 50.05010
38.57367 27.56523 4.855260 50.08791
38.61033 27.49264 4.866460 50.15994
38.64700 27.42108 4.874015 49.93596
38.68367 27.34858 4.880158 50.00797
38.72034 27.27583 4.884192 50.03320
38.75700 27.20244 4.888058 50.10144
38.79367 27.13075 4.891118 49.85140
38.83034 27.05669 4.893198 50.00694
38.86700 26.98372 4.894313 50.23986
38.90367 26.90918 4.893933 50.00502
38.94033 26.83534 4.891797 49.98285
38.97700 26.76092 4.887904 49.94911
39.01367 26.68631 4.879622 49.85598
39.05033 26.61210 4.868012 50.08736
39.08700 26.53791 4.854797 50.05380
39.12366 26.46414 4.837846 49.89278
39.16033 26.38881 4.818848 49.95106
39.19700 26.31454 4.799616 49.98725
39.23367 26.24032 4.780296 49.88260
39.27033 26.16512 4.759312 49.91440
39.30700 26.08982 4.737516 49.77774
39.34366 26.01517 4.716210 50.07934
39.38034 25.93971 4.694723 50.08986
39.41700 25.86535 4.671371 50.09078
39.45367 25.78979 4.648050 50.12183
39.49033 25.71524 4.626450 49.96701
39.52700 25.63950 4.602878 49.93506
39.56367 25.56581 4.579565 50.02883
39.60034 25.48957 4.555588 50.08037
39.63700 25.41496 4.531160 49.83360
39.67366 25.33888 4.507126 49.95642
39.71033 25.26434 4.484317 50.11435
39.74700 25.18834 4.458800 49.85675
39.78366 25.11352 4.433830 49.85012
39.82033 25.03799 4.408840 49.88360
39.85700 24.96268 4.384036 49.95772
39.89366 24.88738 4.357578 50.01460
39.93033 24.81153 4.333793 50.02722
39.96700 24.73703 4.308118 49.90957
40.00366 24.66144 4.285256 50.07398
40.04033 24.58532 4.260022 50.05934
40.07700 24.51082 4.237915 50.11598
40.11367 24.43622 4.210676 50.07982
40.15033 24.35982 4.188248 49.98047
40.18700 24.28387 4.162200 49.97150
40.22367 24.21000 4.139238 49.87433
40.26033 24.13424 4.115910 49.92032
40.29700 24.05886 4.090328 49.82830
40.33366 23.98377 4.067934 49.99856
40.37033 23.90816 4.044153 49.90126
40.40700 23.83314 4.023447 50.05402
40.44366 23.75836 3.997675 49.94616
40.48033 23.68274 3.975956 49.96118
40.51700 23.60836 3.952392 49.96820
40.55366 23.53345 3.927751 49.96591
40.59033 23.45742 3.906370 50.06450
40.62700 23.38256 3.882818 50.15570
40.66367 23.30697 3.861709 50.03779
40.70033 23.23171 3.838341 50.08950
40.73700 23.15716 3.815047 49.94844
40.77367 23.08216 3.792615 49.90097
40.81033 23.00753 3.771786 49.85815
40.84700 22.93010 3.748517 50.01516
40.88367 22.85612 3.727665 49.84628
40.92034 22.78127 3.704248 49.96816
40.95700 22.70696 3.682822 50.02039
40.99367 22.63129 3.660407 49.82802
41.03033 22.55510 3.637080 50.08305
41.06700 22.48090 3.615292 50.11904
41.10367 22.40537 3.592056 49.99722
41.14033 22.33090 3.569025 49.83094
41.17700 22.25537 3.547194 49.90640
41.21367 22.17966 3.522980 50.08880
41.25033 22.10530 3.501136 49.94661
41.28700 22.02974 3.478634 50.03627
41.32367 21.95485 3.454258 50.05110
41.36033 21.87850 3.431135 49.91889
41.39700 21.80449 3.407962 50.08972
41.43367 21.72912 3.384111 49.94171
41.47033 21.65432 3.361255 50.13703
41.50700 21.57901 3.336855 49.94574
41.54367 21.50389 3.315201 50.15418
41.58033 21.42827 3.292154 49.86988
41.61700 21.35325 3.266218 49.94638
41.65367 21.27776 3.242600 49.96124
41.69033 21.20174 3.220808 49.94202
41.72700 21.12725 3.196151 49.91053
41.76367 21.05186 3.173804 50.01286
41.80033 20.97620 3.149868 50.03779
41.83700 20.90206 3.125454 49.88500
41.87366 20.82582 3.104150 50.20120
41.91033 20.75076 3.079068 49.89454
41.94700 20.67595 3.058050 49.90363
41.98367 20.60043 3.037094 49.97390
42.02033 20.52519 3.012065 49.97295
42.05700 20.45071 2.989959 49.99772
42.09366 20.37549 2.970205 50.11508
42.13033 20.30089 2.947405 50.12024
42.16700 20.22496 2.927013 49.95490
42.20367 20.15044 2.905646 49.96539
42.24033 20.07484 2.884633 50.10262
42.27700 19.99998 2.864256 49.95570
42.31367 19.92498 2.844050 50.09620
42.35034 19.85064 2.824144 49.97198
42.38700 19.77478 2.805738 49.89346
42.42366 19.70001 2.787300 50.09534
42.46033 19.62508 2.769121 49.91968
42.49700 19.54960 2.750469 50.03881
42.53366 19.47516 2.732912 50.04412
42.57033 19.40077 2.715655 50.03618
42.60700 19.32518 2.697789 50.13904
42.64366 19.25012 2.682478 49.95941
42.68033 19.17609 2.666324 49.99209
42.71700 19.10197 2.651638 50.10705
42.75367 19.02689 2.637722 49.97856
42.79033 18.95205 2.620782 50.02434
42.82700 18.87788 2.607668 50.08658
42.86367 18.80326 2.593277 50.02991
42.90033 18.72846 2.579798 49.82009
42.93700 18.65380 2.566963 49.94415
42.97367 18.57872 2.555380 50.08520
43.01033 18.50405 2.541506 50.13300
43.04700 18.43006 2.529803 49.79616
43.08366 18.35558 2.517866 49.84512
43.12033 18.28152 2.508068 49.92922
43.15700 18.20636 2.496216 49.99674
43.19366 18.13256 2.486404 49.96771
43.23033 18.05794 2.476156 49.82730
43.26700 17.98426 2.466610 49.93459
43.30367 17.91056 2.457699 49.93922
43.34033 17.83539 2.447936 50.05898
43.37700 17.76201 2.439340 50.04006
43.41367 17.68775 2.430844 49.96720
43.45033 17.61364 2.422540 49.98363
43.48700 17.53993 2.414633 49.98224
43.52367 17.46618 2.406650 49.94122
43.56033 17.39271 2.399041 49.91876
43.59700 17.31732 2.391552 49.99297
43.63367 17.24371 2.383219 50.04154
43.67033 17.17111 2.376010 49.99650
43.70700 17.09665 2.368808 50.08574
43.74367 17.02242 2.361658 50.06464
43.78033 16.94863 2.354552 50.04936
43.81700 16.87442 2.347640 50.01376
43.85367 16.80066 2.340710 49.92727
43.89033 16.72776 2.334020 50.02212
43.92700 16.65390 2.327632 50.01356
43.96367 16.57924 2.321358 49.87198
44.00033 16.50619 2.315236 49.98088
44.03700 16.43201 2.309183 49.88568
44.07367 16.35792 2.303535 50.00101
44.11033 16.28505 2.297873 49.91324
44.14700 16.21117 2.292339 50.01553
44.18367 16.13777 2.287090 49.93539
44.22033 16.06403 2.282011 50.04934
44.25700 15.99025 2.277156 50.03416
44.29367 15.91764 2.272298 50.06844
44.33033 15.84367 2.267605 50.22662
44.36700 15.76947 2.263246 49.90284
44.40367 15.69497 2.258779 50.05974
44.44033 15.62296 2.254660 49.97055
44.47700 15.54902 2.250648 49.93792
44.51367 15.47567 2.246624 50.09456
44.55033 15.40083 2.242818 50.06138
44.58700 15.32761 2.239106 50.07174
44.62366 15.25447 2.235544 49.93140
44.66033 15.18059 2.232127 49.87159
44.69700 15.10774 2.228794 49.86378
44.73367 15.03378 2.225585 50.11139
44.77033 14.96041 2.222428 50.03626
44.80700 14.88775 2.219455 49.91046
44.84366 14.81348 2.216663 49.97780
44.88033 14.74070 2.213810 50.08488
44.91700 14.66681 2.211084 50.03696
44.95367 14.59335 2.208536 50.06257
44.99033 14.51971 2.206035 50.03085
45.02700 14.44685 2.203718 49.99228
45.06367 14.37355 2.201366 49.97237
45.10034 14.30035 2.199200 50.13526
45.13700 14.22690 2.197133 49.98706
45.17366 14.15350 2.195187 49.93946
45.21033 14.07996 2.193340 49.89310
45.24700 14.00634 2.191650 49.99086
45.28366 13.93348 2.189890 50.04941
45.32033 13.85965 2.188394 50.04786
45.35700 13.78594 2.186685 50.02280
45.39366 13.71298 2.185215 50.07320
45.43033 13.63902 2.183746 50.09219
45.46700 13.56528 2.182408 50.10352
45.50367 13.49188 2.181086 50.11832
45.54033 13.41898 2.179892 49.96335
45.57700 13.34589 2.178812 50.08138
45.61367 13.27210 2.177832 49.92370
45.65033 13.19837 2.176598 49.89537
45.68700 13.12475 2.175694 49.95411
45.72367 13.05194 2.174474 49.95616
45.76033 12.97788 2.173449 49.97904
45.79700 12.90554 2.172547 49.96602
45.83366 12.83228 2.171572 50.03356
45.87033 12.75854 2.170592 50.00693
45.90700 12.68505 2.169700 49.97469
45.94366 12.61240 2.168684 49.84532
45.98033 12.53865 2.167788 49.89526
46.01700 12.46518 2.166963 50.11660
46.05367 12.39150 2.166113 49.92154
46.09033 12.31865 2.165158 50.06682
46.12700 12.24534 2.164463 49.96686
46.16367 12.17286 2.163711 49.93369
46.20033 12.09889 2.162966 50.02784
46.23700 12.02464 2.162242 50.04535
46.27367 11.95234 2.161541 49.97053
46.31033 11.87860 2.160864 49.97732
46.34700 11.80557 2.160482 50.00422
46.38367 11.73184 2.159983 50.05298
46.42033 11.65853 2.159590 49.82285
46.45700 11.58497 2.159004 49.94908
46.49367 11.51255 2.158705 49.97848
46.53033 11.43884 2.158346 50.02112
46.56700 11.36484 2.157783 49.99043
46.60367 11.29220 2.157544 50.02816
46.64033 11.21849 2.157072 49.96740
46.67700 11.14533 2.156719 49.88359
46.71367 11.07258 2.156235 50.16355
46.75033 10.99822 2.156037 50.04045
46.78700 10.92608 2.155630 50.03296
46.82367 10.85193 2.155236 50.09034
46.86033 10.77816 2.154927 50.02678
46.89700 10.70557 2.154627 50.02486
46.93367 10.63268 2.154350 49.95186
46.97033 10.55857 2.154048 50.17660
47.00700 10.48508 2.153605 50.05238
47.04367 10.41292 2.153352 49.85209
47.08033 10.33915 2.153049 50.09544
47.11700 10.26555 2.152684 49.93842
47.15367 10.19276 2.152480 49.96758
47.19033 10.11941 2.152153 49.96244
47.22700 10.04604 2.151934 49.97572
47.26367 9.971942 2.151793 49.95678
47.30033 9.898851 2.151486 50.04602
47.33700 9.826110 2.151302 50.00996
47.37366 9.752202 2.151070 50.06611
47.41033 9.679851 2.150966 49.95421
47.44700 9.605645 2.150786 50.09584
47.48367 9.533705 2.150602 49.92958
47.52033 9.460054 2.150408 49.85874
47.55700 9.385968 2.150208 50.12682
47.59366 9.313199 2.150100 49.96580
47.63033 9.239912 2.149840 50.04490
47.66700 9.165845 2.149722 50.07220
47.70367 9.093226 2.149564 50.02038
47.74033 9.019231 2.149556 50.00030
47.77700 8.945871 2.149306 50.11422
47.81367 8.873141 2.149203 49.96946
47.85034 8.799962 2.149045 49.96958
47.88700 8.726147 2.148992 49.91582
47.92366 8.653024 2.148824 49.96940
47.96033 8.579820 2.148757 49.98156
47.99700 8.506337 2.148690 49.78991
48.03366 8.432705 2.148639 50.05795
48.07033 8.359939 2.148483 49.96185
48.10700 8.286298 2.148422 50.02379
48.14366 8.213355 2.148328 49.93310
48.18033 8.139518 2.148362 50.10448
48.21700 8.066025 2.148304 50.06158
48.25367 7.993158 2.148375 49.87766
48.29033 7.919700 2.148478 50.03822
48.32700 7.846228 2.148512 49.98861
48.36367 7.773131 2.148534 49.96984
48.40033 7.699946 2.148679 50.14654
48.43700 7.627130 2.148831 49.94502
48.47367 7.552886 2.148958 50.01359
48.51033 7.480274 2.149241 49.95069
48.54700 7.406536 2.149354 49.92714
48.58366 7.333748 2.149483 50.12720
48.62033 7.260855 2.149636 49.82098
48.65700 7.187985 2.149756 50.09972
48.69366 7.114170 2.149723 49.86369
48.73033 7.041389 2.149905 50.11200
48.76700 6.967194 2.149812 49.91832
48.80367 6.894045 2.149805 50.18346
48.84033 6.820605 2.149927 50.10086
48.87700 6.747735 2.149968 49.95960
48.91367 6.673950 2.150122 49.98674
48.95033 6.600616 2.150366 50.01738
48.98700 6.527332 2.150693 49.97409
49.02367 6.454406 2.151211 49.81558
49.06033 6.381118 2.151666 49.90104
49.09700 6.308170 2.152563 50.06541
49.13367 6.234851 2.153457 50.00221
49.17033 6.161403 2.154454 49.98091
49.20700 6.087832 2.155664 49.98864
49.24367 6.015754 2.156778 49.89815
49.28033 5.941997 2.158011 49.88948
49.31700 5.869097 2.159246 49.99542
49.33700 5.828510 2.159930 50.01194